<mujoco model="humanoid">
  <default>
    <!-- Disable self-collision by using separate contact masks; allow floor contact only. -->
    <geom contype="1" conaffinity="2" group="1" solref="0.01 1" solimp="0.95 0.99 1e-5" friction="0.8 0.01 0.01"/>
    <!-- More damping/armature to stabilize position control on light links. -->
    <joint damping="0.5" armature="0.02" frictionloss="0.02"/>
  </default>
  <compiler angle="radian" meshdir="meshes/"/>
  <option gravity="0 0 0" timestep="0.001" integrator="implicit">
    <flag limit="enable"/>
  </option>

  <asset>
    <mesh name="pelvis" content_type="model/stl" file="pelvis.STL"/>
    <mesh name="waist_yaw_link" content_type="model/stl" file="waist_yaw_link.STL"/>
    <mesh name="head_yaw_link" content_type="model/stl" file="head_yaw_link.STL"/>
    <mesh name="head_pitch_link" content_type="model/stl" file="head_pitch_link.STL"/>
    <mesh name="head_roll_link" content_type="model/stl" file="head_roll_link.STL"/>
    <mesh name="shoulder_pitch_l_link" content_type="model/stl" file="shoulder_pitch_l_link.STL"/>
    <mesh name="shoulder_roll_l_link" content_type="model/stl" file="shoulder_roll_l_link.STL"/>
    <mesh name="shoulder_yaw_l_link" content_type="model/stl" file="shoulder_yaw_l_link.STL"/>
    <mesh name="elbow_pitch_l_link" content_type="model/stl" file="elbow_pitch_l_link.STL"/>
    <mesh name="elbow_yaw_l_link" content_type="model/stl" file="elbow_yaw_l_link.STL"/>
    <mesh name="wrist_pitch_l_link" content_type="model/stl" file="wrist_pitch_l_link.STL"/>
    <mesh name="wrist_roll_l_link" content_type="model/stl" file="wrist_roll_l_link.STL"/>
    <mesh name="shoulder_pitch_r_link" content_type="model/stl" file="shoulder_pitch_r_link.STL"/>
    <mesh name="shoulder_roll_r_link" content_type="model/stl" file="shoulder_roll_r_link.STL"/>
    <mesh name="shoulder_yaw_r_link" content_type="model/stl" file="shoulder_yaw_r_link.STL"/>
    <mesh name="elbow_pitch_r_link" content_type="model/stl" file="elbow_pitch_r_link.STL"/>
    <mesh name="elbow_yaw_r_link" content_type="model/stl" file="elbow_yaw_r_link.STL"/>
    <mesh name="wrist_pitch_r_link" content_type="model/stl" file="wrist_pitch_r_link.STL"/>
    <mesh name="wrist_roll_r_link" content_type="model/stl" file="wrist_roll_r_link.STL"/>
    <mesh name="palm" content_type="model/stl" file="palm.STL"/>
    <mesh name="index_link_0" content_type="model/stl" file="index_link_0.STL"/>
    <mesh name="index_link_1" content_type="model/stl" file="index_link_1.STL"/>
    <mesh name="middle_link_0" content_type="model/stl" file="middle_link_0.STL"/>
    <mesh name="middle_link_1" content_type="model/stl" file="middle_link_1.STL"/>
    <mesh name="ring_link_0" content_type="model/stl" file="ring_link_0.STL"/>
    <mesh name="ring_link_1" content_type="model/stl" file="ring_link_1.STL"/>
    <mesh name="little_link_0" content_type="model/stl" file="little_link_0.STL"/>
    <mesh name="little_link_1" content_type="model/stl" file="little_link_1.STL"/>
    <mesh name="thumb_link_0" content_type="model/stl" file="thumb_link_0.STL"/>
    <mesh name="thumb_link_1" content_type="model/stl" file="thumb_link_1.STL"/>
    <mesh name="thumb_link_2" content_type="model/stl" file="thumb_link_2.STL"/>
    <mesh name="thumb_link_3" content_type="model/stl" file="thumb_link_3.STL"/>
  </asset>

  <worldbody>
    <geom name="floor" type="plane" size="5 5 0.1" pos="0 0 0" rgba="0.9 0.9 0.9 1" contype="2" conaffinity="1" group="1"/>
    <light name="dome_light" pos="0 0 3" dir="0 0 -1" diffuse="0.8 0.8 0.8" specular="0.1 0.1 0.1" directional="false"/>
    <geom name="axis_x" type="cylinder" size="0.005 0.05" pos="0.05 0 0" quat="0.70710678 0 0.70710678 0" rgba="1 0 0 1" contype="0" conaffinity="0"/>
    <geom name="axis_y" type="cylinder" size="0.005 0.05" pos="0 0.05 0" quat="0.70710678 -0.70710678 0 0" rgba="0 1 0 1" contype="0" conaffinity="0"/>
    <geom name="axis_z" type="cylinder" size="0.005 0.05" pos="0 0 0.05" rgba="0 0 1 1" contype="0" conaffinity="0"/>
    <body name="tracker_target" mocap="true">
      <geom name="tracker_target_geom" type="sphere" size="0.01" rgba="1 0.2 0.2 1" contype="0" conaffinity="0"/>
      <geom name="tracker_target_axis_x" type="cylinder" size="0.002 0.03" pos="0.03 0 0" quat="0.70710678 0 0.70710678 0" rgba="1 0 0 1" contype="0" conaffinity="0"/>
      <geom name="tracker_target_axis_y" type="cylinder" size="0.002 0.03" pos="0 0.03 0" quat="0.70710678 -0.70710678 0 0" rgba="0 1 0 1" contype="0" conaffinity="0"/>
      <geom name="tracker_target_axis_z" type="cylinder" size="0.002 0.03" pos="0 0 0.03" rgba="0 0 1 1" contype="0" conaffinity="0"/>
    </body>
    <body name="model_root" pos="0 0 0.75" quat="0.70710678 0 0 0.70710678">
    <geom type="mesh" rgba="0.752941 0.752941 0.752941 1" mesh="pelvis"/>
    <geom type="mesh" rgba="0.752941 0.752941 0.752941 1" mesh="waist_yaw_link"/>
    <geom pos="-0.002 0 0.56508" quat="1 0 0 0" type="mesh" rgba="0.752941 0.752941 0.752941 1" mesh="head_yaw_link"/>
    <geom pos="0.01255 0 0.59548" quat="0.991445 0 0.130526 0" type="mesh" rgba="0.752941 0.752941 0.752941 1" mesh="head_pitch_link"/>
    <geom pos="0.01255 0 0.59548" quat="0.991445 0 0.130526 0" type="mesh" rgba="0.752941 0.752941 0.752941 1" mesh="head_roll_link"/>
    <geom pos="0 0.14539 0.37721" quat="0.999048 0.0436192 0 0" type="mesh" rgba="0.752941 0.752941 0.752941 1" mesh="shoulder_pitch_l_link"/>
    <geom pos="0 0.213131 0.383137" quat="0.999048 0.0436192 0 0" type="mesh" rgba="0.752941 0.752941 0.752941 1" mesh="shoulder_roll_l_link"/>
    <geom pos="0 0.222065 0.281027" quat="0.999048 0.0436192 0 0" type="mesh" rgba="0.752941 0.752941 0.752941 1" mesh="shoulder_yaw_l_link"/>
    <geom pos="0.02 0.239278 0.0842781" quat="0.999048 0.0436192 0 0" type="mesh" rgba="0.752941 0.752941 0.752941 1" mesh="elbow_pitch_l_link"/>
    <geom pos="0 0.24401 0.0301848" quat="0.999048 0.0436192 0 0" type="mesh" rgba="0.752941 0.752941 0.752941 1" mesh="elbow_yaw_l_link"/>
    <geom pos="0 0.262449 -0.157623" quat="0.999048 0.0436192 0 0" type="mesh" rgba="0.752941 0.752941 0.752941 1" mesh="wrist_pitch_l_link"/>
    <geom pos="5.0485e-05 0.264192 -0.177547" quat="0.999048 0.0436192 0 0" type="mesh" rgba="0.752941 0.752941 0.752941 1" mesh="wrist_roll_l_link"/>
    <body name="shoulder_pitch_r_link" pos="0 -0.14539 0.37721" quat="0.999048 -0.0436192 0 0">
      <inertial pos="0.00754 -0.064361 -3.7e-05" quat="0.582335 0.401219 -0.582317 0.401019" mass="1.03063" diaginertia="0.000636 0.000545537 0.000470463"/>
      <joint name="shoulder_pitch_r_joint" pos="0 0 0" axis="0 1 0" range="-2.96 0" actuatorfrcrange="-91 91"/>
      <geom type="mesh" rgba="0.752941 0.752941 0.752941 1" mesh="shoulder_pitch_r_link"/>
      <body name="shoulder_roll_r_link" pos="0 -0.068 0">
        <inertial pos="0.00106653 -0.00220629 -0.0441161" quat="0.705886 -0.0128765 -0.00329147 0.7082" mass="0.412601" diaginertia="0.00126407 0.000939019 0.000895909"/>
        <joint name="shoulder_roll_r_joint" pos="0 0 0" axis="1 0 0" range="-2 -0.1" actuatorfrcrange="-60 60"/>
        <geom type="mesh" rgba="0.752941 0.752941 0.752941 1" mesh="shoulder_roll_r_link"/>
        <body name="shoulder_yaw_r_link" pos="0 0 -0.1025">
          <inertial pos="0.008387 -0.00373 -0.11229" quat="0.95062 0.00536915 0.0606486 -0.304326" mass="1.3076" diaginertia="0.00944038 0.00923249 0.000707129"/>
          <joint name="shoulder_yaw_r_joint" pos="0 0 0" axis="0 0 1" range="0 2.5" actuatorfrcrange="-30 30"/>
          <geom type="mesh" rgba="0.752941 0.752941 0.752941 1" mesh="shoulder_yaw_r_link"/>
          <body name="elbow_pitch_r_link" pos="0.02 0 -0.1975">
            <inertial pos="-0.014369 9e-05 -0.024267" quat="0.622759 0.501992 -0.379872 0.464622" mass="0.222661" diaginertia="0.000398305 0.000361097 0.000199597"/>
            <joint name="elbow_pitch_r_joint" pos="0 0 0" axis="0 1 0" range="-2 0" actuatorfrcrange="-30 30"/>
            <geom type="mesh" rgba="0.752941 0.752941 0.752941 1" mesh="elbow_pitch_r_link"/>
            <body name="elbow_yaw_r_link" pos="-0.02 0 -0.0543">
              <inertial pos="8e-05 0.00115 -0.069083" quat="0.999899 -0.012607 0.000668448 0.00659261" mass="0.990079" diaginertia="0.00296102 0.00287955 0.000420432"/>
              <joint name="elbow_yaw_r_joint" pos="0 0 0" axis="0 0 1" range="-2.9671 2.9671" actuatorfrcrange="-15 15"/>
              <geom type="mesh" rgba="0.752941 0.752941 0.752941 1" mesh="elbow_yaw_r_link"/>
              <body name="wrist_pitch_r_link" pos="0 -0.002 -0.1887">
                <inertial pos="0.005341 -0.000652 -0.018511" quat="0.614988 0.28303 0.66524 0.314863" mass="0.266415" diaginertia="0.000116841 0.000110463 7.36959e-05"/>
                <joint name="wrist_pitch_r_joint" pos="0 0 0" axis="0 1 0" range="-0.5 0.6" actuatorfrcrange="-9 9"/>
                <geom type="mesh" rgba="0.752941 0.752941 0.752941 1" mesh="wrist_pitch_r_link"/>
                <body name="wrist_roll_r_link" pos="5.0485e-05 0 -0.02">
                  <inertial pos="-0.000326775 -0.0611164 -0.0317169" quat="0.622306 0.778331 -0.0712962 0.0430443" mass="0.365684" diaginertia="0.000467207 0.000452767 0.000155639"/>
                  <joint name="wrist_roll_r_joint" pos="0 0 0" axis="1 0 0" range="-0.5 0.5" actuatorfrcrange="-9 9"/>
                  <geom type="mesh" rgba="0.752941 0.752941 0.752941 1" mesh="wrist_roll_r_link"/>
                  <site name="hand_tcp" pos="0 0 -0.0375" quat="0.5 0.5 -0.5 -0.5" size="0.005" rgba="1 0 0 1"/>
                  <geom pos="0 0 -0.0375" quat="0.5 0.5 -0.5 -0.5" type="mesh" rgba="1 1 1 1" mesh="palm"/>
                  <body name="index_link_0" pos="0.027269 -0.000285329 -0.1741" quat="0.491196 -0.508652 -0.508648 0.491199">
                    <inertial pos="0.0031774 0.017383 0.00090008" quat="0.491211 0.50867 -0.491172 0.508643" mass="0.05" diaginertia="6.9398e-07 6.62871e-07 2.10909e-07"/>
                    <joint name="index_joint_0" pos="0 0 0" axis="0 0 -1" range="0 1.1" actuatorfrcrange="-50 50"/>
                    <geom type="mesh" rgba="1 1 1 1" mesh="index_link_0"/>
                    <body name="index_link_1" pos="0.0070171 0.037468 -0.00215">
                      <inertial pos="-0.00196942 0.0195896 0.00304996" quat="0.531315 0.466884 -0.531044 0.4666" mass="0.025001" diaginertia="7.83076e-07 7.73728e-07 8.57466e-08"/>
                      <joint name="index_joint_1" pos="0 0 0" axis="0 0 -1" range="0 1.7" actuatorfrcrange="-50 50"/>
                      <geom type="mesh" rgba="1 1 1 1" mesh="index_link_1"/>
                    </body>
                  </body>
                  <body name="middle_link_0" pos="0.00795 -0.00028533 -0.1746" quat="0.499998 -0.500002 -0.499998 0.500002">
                    <inertial pos="0.0030737 0.017402 0.00090013" quat="0.489693 0.510131 -0.489653 0.510105" mass="0.05" diaginertia="6.9397e-07 6.62865e-07 2.10915e-07"/>
                    <joint name="middle_joint_0" pos="0 0 0" axis="0 0 -1" range="0 1.1" actuatorfrcrange="-50 50"/>
                    <geom type="mesh" rgba="1 1 1 1" mesh="middle_link_0"/>
                    <body name="middle_link_1" pos="0.0067937 0.037509 -0.00215">
                      <inertial pos="-0.00192072 0.0207966 0.00304996" quat="0.531767 0.466253 -0.531604 0.466079" mass="0.025001" diaginertia="9.8509e-07 9.74504e-07 9.24276e-08"/>
                      <joint name="middle_joint_1" pos="0 0 0" axis="0 0 -1" range="0 1.7" actuatorfrcrange="-50 50"/>
                      <geom type="mesh" rgba="1 1 1 1" mesh="middle_link_1"/>
                    </body>
                  </body>
                  <body name="ring_link_0" pos="-0.0112844 -0.00028533 -0.17431" quat="-0.512919 0.486738 0.486742 -0.512915">
                    <inertial pos="0.0030737 0.017402 0.00090015" quat="0.489691 0.510129 -0.489655 0.510107" mass="0.05" diaginertia="6.9397e-07 6.62865e-07 2.10915e-07"/>
                    <joint name="ring_joint_0" pos="0 0 0" axis="0 0 -1" range="0 1.1" actuatorfrcrange="-50 50"/>
                    <geom type="mesh" rgba="1 1 1 1" mesh="ring_link_0"/>
                    <body name="ring_link_1" pos="0.0067937 0.037509 -0.00215">
                      <inertial pos="-0.00217501 0.0195676 0.00304996" quat="0.528871 0.469673 -0.528578 0.46937" mass="0.025001" diaginertia="7.8306e-07 7.73711e-07 8.57512e-08"/>
                      <joint name="ring_joint_1" pos="0 0 0" axis="0 0 -1" range="0 1.7" actuatorfrcrange="-50 50"/>
                      <geom type="mesh" rgba="1 1 1 1" mesh="ring_link_1"/>
                    </body>
                  </body>
                  <body name="little_link_0" pos="-0.030477 -0.000285331 -0.17301" quat="-0.525485 0.473145 0.473149 -0.525481">
                    <inertial pos="0.0030737 0.017402 0.00090014" quat="0.489692 0.510129 -0.489654 0.510107" mass="0.05" diaginertia="6.9398e-07 6.62865e-07 2.10915e-07"/>
                    <joint name="little_joint_0" pos="0 0 0" axis="0 0 -1" range="0 1.1" actuatorfrcrange="-100 100"/>
                    <geom type="mesh" rgba="1 1 1 1" mesh="little_link_0"/>
                    <body name="little_link_1" pos="0.0067937 0.037509 -0.00215">
                      <inertial pos="-0.0024745 0.0162038 0.0030531" quat="0.52893 0.473909 -0.524861 0.469216" mass="0.025001" diaginertia="4.5008e-07 4.45103e-07 6.66825e-08"/>
                      <joint name="little_joint_1" pos="0 0 0" axis="0 0 -1" range="0 1.7" actuatorfrcrange="-50 50"/>
                      <geom type="mesh" rgba="1 1 1 1" mesh="little_link_1"/>
                    </body>
                  </body>
                  <body name="thumb_link_0" pos="0.02045 0.02296 -0.09635" quat="1.34008e-08 -1.82321e-06 -1 1.8366e-06">
                    <inertial pos="-0.0078715 0.0065154 0.00388" quat="0.515015 0.680854 0.408023 0.323596" mass="0.05" diaginertia="8.66026e-08 6.8732e-08 4.94194e-08"/>
                    <joint name="thumb_joint_0" pos="0 0 0" axis="0 0 -1" range="0.3 1.2" actuatorfrcrange="-50 50"/>
                    <geom type="mesh" rgba="1 1 1 1" mesh="thumb_link_0"/>
                    <body name="thumb_link_1" pos="-0.012782 0.013348 0.0022" quat="0.0996843 0.0996847 0.700046 0.700044">
                      <inertial pos="0.021932 0.012785 -0.0047886" quat="-0.254484 0.660712 0.251903 0.659729" mass="0.03" diaginertia="2.78601e-06 2.43937e-06 8.64621e-07"/>
                      <joint name="thumb_joint_1" pos="0 0 0" axis="0 0 1" range="0 0.5" actuatorfrcrange="-50 50"/>
                      <geom type="mesh" rgba="1 1 1 1" mesh="thumb_link_1"/>
                      <body name="thumb_link_2" pos="0.05507 0.025553 -0.00355" quat="1.34924e-11 3.67321e-06 1 3.67321e-06">
                        <inertial pos="-0.0060688 0.011295 0.00099972" quat="0.307389 0.636718 -0.307548 0.636802" mass="0.025" diaginertia="4.6531e-07 4.48089e-07 2.45661e-07"/>
                        <joint name="thumb_joint_2" pos="0 0 0" axis="0 0 -1" range="0 0.5" actuatorfrcrange="-50 50"/>
                        <geom type="mesh" rgba="1 1 1 1" mesh="thumb_link_2"/>
                        <body name="thumb_link_3" pos="-0.016763 0.023079 -0.00255">
                          <inertial pos="-0.00928884 0.0049534 0.00355337" quat="0.265776 0.655677 -0.263615 0.655712" mass="0.020001" diaginertia="2.01362e-07 1.96305e-07 8.26405e-08"/>
                          <joint name="thumb_joint_3" pos="0 0 0" axis="0 0 -1" range="0 0.4" actuatorfrcrange="-50 50"/>
                          <geom type="mesh" rgba="1 1 1 1" mesh="thumb_link_3"/>
                        </body>
                      </body>
                    </body>
                  </body>
                </body>
              </body>
            </body>
          </body>
        </body>
      </body>
    </body>
    </body>
  </worldbody>

  <actuator>
    <position name="shoulder_pitch_r_joint" joint="shoulder_pitch_r_joint" ctrlrange="-2.96 0" kp="25" kv="5" ctrllimited="true"/>
    <position name="shoulder_roll_r_joint" joint="shoulder_roll_r_joint" ctrlrange="-2 -0.1" kp="25" kv="5" ctrllimited="true"/>
    <position name="shoulder_yaw_r_joint" joint="shoulder_yaw_r_joint" ctrlrange="0 2.5" kp="25" kv="5" ctrllimited="true"/>
    <position name="elbow_pitch_r_joint" joint="elbow_pitch_r_joint" ctrlrange="-2 0" kp="25" kv="5" ctrllimited="true"/>
    <position name="elbow_yaw_r_joint" joint="elbow_yaw_r_joint" ctrlrange="-2.9671 2.9671" kp="25" kv="5" ctrllimited="true"/>
    <position name="wrist_pitch_r_joint" joint="wrist_pitch_r_joint" ctrlrange="-0.5 0.6" kp="25" kv="5" ctrllimited="true"/>
    <position name="wrist_roll_r_joint" joint="wrist_roll_r_joint" ctrlrange="-0.5 0.5" kp="25" kv="5" ctrllimited="true"/>
    <position name="index_joint_0" joint="index_joint_0" ctrlrange="0 1.1" kp="10" kv="2" ctrllimited="true"/>
    <position name="index_joint_1" joint="index_joint_1" ctrlrange="0 1.7" kp="10" kv="2" ctrllimited="true"/>
    <position name="middle_joint_0" joint="middle_joint_0" ctrlrange="0 1.1" kp="10" kv="2" ctrllimited="true"/>
    <position name="middle_joint_1" joint="middle_joint_1" ctrlrange="0 1.7" kp="10" kv="2" ctrllimited="true"/>
    <position name="ring_joint_0" joint="ring_joint_0" ctrlrange="0 1.1" kp="10" kv="2" ctrllimited="true"/>
    <position name="ring_joint_1" joint="ring_joint_1" ctrlrange="0 1.7" kp="10" kv="2" ctrllimited="true"/>
    <position name="little_joint_0" joint="little_joint_0" ctrlrange="0 1.1" kp="10" kv="2" ctrllimited="true"/>
    <position name="little_joint_1" joint="little_joint_1" ctrlrange="0 1.7" kp="10" kv="2" ctrllimited="true"/>
    <position name="thumb_joint_0" joint="thumb_joint_0" ctrlrange="0.3 1.2" kp="10" kv="2" ctrllimited="true"/>
    <position name="thumb_joint_1" joint="thumb_joint_1" ctrlrange="0 0.5" kp="10" kv="2" ctrllimited="true"/>
    <position name="thumb_joint_2" joint="thumb_joint_2" ctrlrange="0 0.5" kp="10" kv="2" ctrllimited="true"/>
    <position name="thumb_joint_3" joint="thumb_joint_3" ctrlrange="0 0.4" kp="10" kv="2" ctrllimited="true"/>
  </actuator>
</mujoco>
