<?xml version="1.0" encoding="utf-8"?>
<!-- This URDF was automatically created by SolidWorks to URDF Exporter! Originally created by Stephen Brawner (brawner@gmail.com) 
     Commit Version: 1.6.0-4-g7f85cfe  Build Version: 1.6.7995.38578
     For more information, please see http://wiki.ros.org/sw_urdf_exporter -->
<robot
  name="humanoid">
  <mujoco>
    <compiler meshdir="meshes"/>
  </mujoco>
  <link name="world"/>
  <joint name="pelvis_fixed_joint" type="fixed">
      <origin
        xyz="0 0 0"
        rpy="0 0 0" />
     <parent link="world"/>
     <child link="pelvis"/>
   </joint>
  <link
    name="pelvis">
    <inertial>
      <origin
        xyz="-0.000641 0.000723  -0.074769"
        rpy="0 0 0" />
      <mass
        value="6.094610" />
      <inertia
        ixx="0.020607"
        ixy="0.004335"
        ixz="0.000046"
        iyy="0.027481"
        iyz="-0.000037"
        izz="0.028105" />
    </inertial>
    <visual>
      <origin
        xyz="0 0 0"
        rpy="0 0 0" />
      <geometry>
        <mesh
          filename="pelvis.STL" />
      </geometry>
      <material
        name="">
        <color
          rgba="0.752941176470588 0.752941176470588 0.752941176470588 1" />
      </material>
    </visual>
    <collision>
      <origin
        xyz="0 0 0"
        rpy="0 0 0" />
      <geometry>
        <mesh
          filename="pelvis.STL" />
      </geometry>
    </collision>
  </link>

  <!-- BEGIN LEG LINKS/Joints
  <link
    name="hip_roll_l_link">
    <inertial>
      <origin
        xyz="-0.001848 0.055849 -0.036017"
        rpy="0 0 0" />
      <mass
        value="0.672983" />
      <inertia
        ixx="0.001020"
        ixy="0.000070"
        ixz="-0.000038"
        iyy="0.003221"
        iyz="-0.000281"
        izz="0.003272" />
    </inertial>
    <visual>
      <origin
        xyz="0 0 0"
        rpy="0 0 0" />
      <geometry>
        <mesh
          filename="hip_roll_l_link.STL" />
      </geometry>
      <material
        name="">
        <color
          rgba="0.752941176470588 0.752941176470588 0.752941176470588 1" />
      </material>
    </visual>
    <collision>
      <origin
        xyz="0 0 0"
        rpy="0 0 0" />
      <geometry>
        <mesh
          filename="hip_roll_l_link.STL" />
      </geometry>
    </collision>
  </link>

  <joint
    name="hip_roll_l_joint"
    type="fixed">
    <origin
      xyz="0 0.028 -0.0857"
      rpy="0 0 0" />
    <parent
      link="pelvis" />
    <child
      link="hip_roll_l_link" />
    <axis
      xyz="1 0 0" />
    <limit effort="160" lower="-0.79" upper="0.79" velocity="15.6"/>
  </joint>

  <link
    name="hip_pitch_l_link">
    <inertial>
      <origin
        xyz="0.001125 0.001644 -0.011770"
        rpy="0 0 0" />
      <mass
        value="4.227933" />
      <inertia
        ixx="0.016785"
        ixy="0.000022"
        ixz="-0.000255"
        iyy="0.025135"
        iyz="0.000012"
        izz="0.015273" />
    </inertial>
    <visual>
      <origin
        xyz="0 0 0"
        rpy="0 0 0" />
      <geometry>
        <mesh
          filename="hip_pitch_l_link.STL" />
      </geometry>
      <material
        name="">
        <color
          rgba="0.752941176470588 0.752941176470588 0.752941176470588 1" />
      </material>
    </visual>
    <collision>
      <origin
        xyz="0 0 0"
        rpy="0 0 0" />
      <geometry>
        <mesh
          filename="hip_pitch_l_link.STL" />
      </geometry>
    </collision>
  </link>

  <joint
    name="hip_pitch_l_joint"
    type="fixed">
    <origin
      xyz="0 0.122 -0.046"
      rpy="0 -1.43 0" />
    <parent
      link="hip_roll_l_link" />
    <child
      link="hip_pitch_l_link" />
    <axis
      xyz="0 1 0" />
    <limit effort="300" lower="-2.79" upper="2.09" velocity="12.5"/>
  </joint>

  <link
    name="hip_yaw_l_link">
    <inertial>
      <origin
        xyz="0.004124 -0.006494 -0.119737"
        rpy="0 0 0" />
      <mass
        value="6.572700" />
      <inertia
        ixx="0.056043"
        ixy="0.000146"
        ixz="-0.000059"
        iyy="0.063286"
        iyz="0.001030"
        izz="0.021108" />
    </inertial>
    <visual>
      <origin
        xyz="0 0 0"
        rpy="0 0 0" />
      <geometry>
        <mesh
          filename="hip_yaw_l_link.STL" />
      </geometry>
      <material
        name="">
        <color
          rgba="0.752941176470588 0.752941176470588 0.752941176470588 1" />
      </material>
    </visual>
    <collision>
      <origin
        xyz="0 0 0"
        rpy="0 0 0" />
      <geometry>
        <mesh
          filename="hip_yaw_l_link.STL" />
      </geometry>
    </collision>
  </link>

  <joint
    name="hip_yaw_l_joint"
    type="fixed">
    <origin
      xyz="0 0 -0.0987"
      rpy="0 0 0" />
    <parent
      link="hip_pitch_l_link" />
    <child
      link="hip_yaw_l_link" />
    <axis
      xyz="0 0 1" />
    <limit effort="160" lower="-1.04" upper="1.04" velocity="15.6"/>  
  </joint>

  <link
    name="knee_pitch_l_link">
    <inertial>
      <origin
        xyz="0.007489 0.001584  -0.167773"
        rpy="0 0 0" />
      <mass
        value="3.017992" />
      <inertia
        ixx="0.035604"
        ixy="0.000037"
        ixz="0.001830"
        iyy="0.036226"
        iyz="0.000475"
        izz="0.001951" />
    </inertial>
    <visual>
      <origin
        xyz="0 0 0"
        rpy="0 0 0" />
      <geometry>
        <mesh
          filename="knee_pitch_l_link.STL" />
      </geometry>
      <material
        name="">
        <color
          rgba="0.752941176470588 0.752941176470588 0.752941176470588 1" />
      </material>
    </visual>
    <collision>
      <origin
        xyz="0 0 0"
        rpy="0 0 0" />
      <geometry>
        <mesh
          filename="knee_pitch_l_link.STL" />
      </geometry>
    </collision>
  </link>

  <joint
    name="knee_pitch_l_joint"
    type="fixed">
    <origin
      xyz="0 -4.2833E-05 -0.3013"
      rpy="0 1.65 0" />
    <parent
      link="hip_yaw_l_link" />
    <child
      link="knee_pitch_l_link" />
    <axis
      xyz="0 1 0" />
    <limit effort="300" lower="0.0" upper="2.39" velocity="12.5"/>
  </joint>

  <link
    name="ankle_pitch_l_link">
    <inertial>
      <origin
        xyz="1.23076545482746E-09 5.88533416445713E-10 -3.14193115968919E-14"
        rpy="0 0 0" />
      <mass
        value="0.111609" />
      <inertia
        ixx="0.000018"
        ixy="9.12795578499149E-18"
        ixz="-8.5550749402341E-12"
        iyy="0.000018"
        iyz="2.59346326737996E-11"
        izz="0.000032" />
    </inertial>
    <visual>
      <origin
        xyz="0 0 0"
        rpy="0 0 0" />
      <geometry>
        <mesh
          filename="ankle_pitch_l_link.STL" />
      </geometry>
      <material
        name="">
        <color
          rgba="0.752941176470588 0.752941176470588 0.752941176470588 1" />
      </material>
    </visual>
    <collision>
      <origin
        xyz="0 0 0"
        rpy="0 0 0" />
      <geometry>
        <mesh
          filename="ankle_pitch_l_link.STL" />
      </geometry>
    </collision>
  </link>

  <joint
    name="ankle_pitch_l_joint"
    type="fixed">
    <origin
      xyz="0 0 -0.4"
      rpy="0 0 0" />
    <parent
      link="knee_pitch_l_link" />
    <child
      link="ankle_pitch_l_link" />
    <axis
      xyz="0 1 0" />
    <limit effort="60" lower="-1.22" upper="0.5236" velocity="12.8"/>
  </joint>

  <link
    name="ankle_roll_l_link">
    <inertial>
      <origin
        xyz="0.021235 -4.62707223369829E-08 -0.032883"
        rpy="0 0 0" />
      <mass
        value="1.017381" />
      <inertia
        ixx="0.001028"
        ixy="4.59557401077979E-08"
        ixz="-0.000622"
        iyy="0.006055"
        iyz="4.78117170569023E-10"
        izz="0.006240" />
    </inertial>
    <visual>
      <origin
        xyz="0 0 0"
        rpy="0 0 0" />
      <geometry>
        <mesh
          filename="ankle_roll_l_link.STL" />
      </geometry>
      <material
        name="">
        <color
          rgba="0.752941176470588 0.752941176470588 0.752941176470588 1" />
      </material>
    </visual>
    <collision>
      <origin
        xyz="0 0 0"
        rpy="0 0 0" />
      <geometry>
        <mesh
          filename="ankle_roll_l_link.STL" />
      </geometry>
    </collision>
  </link>

  <joint
    name="ankle_roll_l_joint"
    type="fixed">
    <origin
      xyz="0 0 0"
      rpy="0 0 0" />
    <parent
      link="ankle_pitch_l_link" />
    <child
      link="ankle_roll_l_link" />
    <axis
      xyz="1 0 0" />
    <limit effort="30" lower="-0.4363" upper="0.4363" velocity="7.8"/>
  </joint>

  <link
    name="hip_roll_r_link">
    <inertial>
      <origin
        xyz="-0.001848 -0.055849 -0.036017"
        rpy="0 0 0" />
      <mass
        value="0.672983" />
      <inertia
        ixx="0.001020"
        ixy="-0.000070"
        ixz="-0.000038"
        iyy="0.003221"
        iyz="0.000281"
        izz="0.003272" />
    </inertial>
    <visual>
      <origin
        xyz="0 0 0"
        rpy="0 0 0" />
      <geometry>
        <mesh
          filename="hip_roll_r_link.STL" />
      </geometry>
      <material
        name="">
        <color
          rgba="0.752941176470588 0.752941176470588 0.752941176470588 1" />
      </material>
    </visual>
    <collision>
      <origin
        xyz="0 0 0"
        rpy="0 0 0" />
      <geometry>
        <mesh
          filename="hip_roll_r_link.STL" />
      </geometry>
    </collision>
  </link>
  <joint
    name="hip_roll_r_joint"
    type="fixed">
    <origin
      xyz="0 -0.028 -0.0857"
      rpy="0 0 0" />
    <parent
      link="pelvis" />
    <child
      link="hip_roll_r_link" />
    <axis
      xyz="1 0 0" />
    <limit effort="160" lower="-0.79" upper="0.79" velocity="15.6"/>
  </joint>
  <link
    name="hip_pitch_r_link">
    <inertial>
      <origin
        xyz="0.001125 -0.001644 -0.011770"
        rpy="0 0 0" />
      <mass
        value="4.227933" />
      <inertia
        ixx="0.016785"
        ixy="-0.000022"
        ixz="-0.000255"
        iyy="0.025135"
        iyz="-0.000012"
        izz="0.015273" />
    </inertial>
    <visual>
      <origin
        xyz="0 0 0"
        rpy="0 0 0" />
      <geometry>
        <mesh
          filename="hip_pitch_r_link.STL" />
      </geometry>
      <material
        name="">
        <color
          rgba="0.752941176470588 0.752941176470588 0.752941176470588 1" />
      </material>
    </visual>
    <collision>
      <origin
        xyz="0 0 0"
        rpy="0 0 0" />
      <geometry>
        <mesh
          filename="hip_pitch_r_link.STL" />
      </geometry>
    </collision>
  </link>
  <joint
    name="hip_pitch_r_joint"
    type="fixed">
    <origin
      xyz="0 -0.122 -0.046"
      rpy="0 -1.43 0" />
    <parent
      link="hip_roll_r_link" />
    <child
      link="hip_pitch_r_link" />
    <axis
      xyz="0 1 0" />
    <limit effort="300" lower="-2.79" upper="2.09" velocity="12.5"/>
  </joint>
  <link
    name="hip_yaw_r_link">
    <inertial>
      <origin
        xyz="0.003740 0.005658 -0.117755"
        rpy="0 0 0" />
      <mass
        value="7.182896" />
      <inertia
        ixx="0.057773"
        ixy="-0.000105"
        ixz="-0.000124"
        iyy="0.064848"
        iyz="-0.001431"
        izz="0.022867" />
    </inertial>
    <visual>
      <origin
        xyz="0 0 0"
        rpy="0 0 0" />
      <geometry>
        <mesh
          filename="hip_yaw_r_link.STL" />
      </geometry>
      <material
        name="">
        <color
          rgba="0.752941176470588 0.752941176470588 0.752941176470588 1" />
      </material>
    </visual>
    <collision>
      <origin
        xyz="0 0 0"
        rpy="0 0 0" />
      <geometry>
        <mesh
          filename="hip_yaw_r_link.STL" />
      </geometry>
    </collision>
  </link>
  <joint
    name="hip_yaw_r_joint"
    type="fixed">
    <origin
      xyz="0 0 -0.0987"
      rpy="0 0 0" />
    <parent
      link="hip_pitch_r_link" />
    <child
      link="hip_yaw_r_link" />
    <axis
      xyz="0 0 1" />
    <limit effort="160" lower="-1.04" upper="1.04" velocity="15.6"/>  
  </joint>

  <link
    name="knee_pitch_r_link">
    <inertial>
      <origin
        xyz="0.007489 -0.001584  -0.167773"
        rpy="0 0 0" />
      <mass
        value="3.017992" />
      <inertia
        ixx="0.035604"
        ixy="-0.000037"
        ixz="0.001830"
        iyy="0.036226"
        iyz="-0.000475"
        izz="0.001951" />
    </inertial>
    <visual>
      <origin
        xyz="0 0 0"
        rpy="0 0 0" />
      <geometry>
        <mesh
          filename="knee_pitch_r_link.STL" />
      </geometry>
      <material
        name="">
        <color
          rgba="0.752941176470588 0.752941176470588 0.752941176470588 1" />
      </material>
    </visual>
    <collision>
      <origin
        xyz="0 0 0"
        rpy="0 0 0" />
      <geometry>
        <mesh
          filename="knee_pitch_r_link.STL" />
      </geometry>
    </collision>
  </link>

  <joint
    name="knee_pitch_r_joint"
    type="fixed">
    <origin
      xyz="0 0.00015001 -0.3013"
      rpy="0 1.65 0" />
    <parent
      link="hip_yaw_r_link" />
    <child
      link="knee_pitch_r_link" />
    <axis
      xyz="0 1 0" />
    <limit effort="300" lower="0.0" upper="2.39" velocity="12.5"/>
  </joint>

  <link
    name="ankle_pitch_r_link">
    <inertial>
      <origin
        xyz="1.23076545482746E-09 -5.88533416445713E-10 -3.14193115968919E-14"
        rpy="0 0 0" />
      <mass
        value="0.111609" />
      <inertia
        ixx="0.000018"
        ixy="-9.12795578499149E-18"
        ixz="-8.5550749402341E-12"
        iyy="0.000018"
        iyz="-2.59346326737996E-11"
        izz="0.000032" />
    </inertial>
    <visual>
      <origin
        xyz="0 0 0"
        rpy="0 0 0" />
      <geometry>
        <mesh
          filename="ankle_pitch_r_link.STL" />
      </geometry>
      <material
        name="">
        <color
          rgba="0.752941176470588 0.752941176470588 0.752941176470588 1" />
      </material>
    </visual>
    <collision>
      <origin
        xyz="0 0 0"
        rpy="0 0 0" />
      <geometry>
        <mesh
          filename="ankle_pitch_r_link.STL" />
      </geometry>
    </collision>
  </link>

  <joint
    name="ankle_pitch_r_joint"
    type="fixed">
    <origin
      xyz="0 0.00074981 -0.4"
      rpy="0 0 0" />
    <parent
      link="knee_pitch_r_link" />
    <child
      link="ankle_pitch_r_link" />
    <axis
      xyz="0 1 0" />
    <limit effort="60" lower="-1.22" upper="0.5236" velocity="12.8"/>
  </joint>

  <link
    name="ankle_roll_r_link">
    <inertial>
      <origin
        xyz="0.021235 4.62707223369829E-08 -0.032883"
        rpy="0 0 0" />
      <mass
        value="1.017381" />
      <inertia
        ixx="0.001028"
        ixy="-4.59557401077979E-08"
        ixz="-0.000622"
        iyy="0.006055"
        iyz="-4.78117170569023E-10"
        izz="0.006240" />
    </inertial>
    <visual>
      <origin
        xyz="0 0 0"
        rpy="0 0 0" />
      <geometry>
        <mesh
          filename="ankle_roll_r_link.STL" />
      </geometry>
      <material
        name="">
        <color
          rgba="0.752941176470588 0.752941176470588 0.752941176470588 1" />
      </material>
    </visual>
    <collision>
      <origin
        xyz="0 0 0"
        rpy="0 0 0" />
      <geometry>
        <mesh
          filename="ankle_roll_r_link.STL" />
      </geometry>
    </collision>
  </link>

  <joint
    name="ankle_roll_r_joint"
    type="fixed">
    <origin
      xyz="0 0 0"
      rpy="0 0 0" />
    <parent
      link="ankle_pitch_r_link" />
    <child
      link="ankle_roll_r_link" />
    <axis
      xyz="1 0 0" />
    <limit effort="30" lower="-0.4363" upper="0.4363" velocity="7.8"/>
  </joint>
  END LEG LINKS/Joints -->

  <link
    name="waist_yaw_link">
    <inertial>
      <origin
        xyz="-0.000568 0.000560 0.231488"
        rpy="0 0 0" />
      <mass
        value="22.445155" />
      <inertia
        ixx="0.429034"
        ixy="-0.000293"
        ixz="0.003462"
        iyy="0.379055"
        iyz="-0.000237"
        izz="0.177142" />
    </inertial>
    <visual>
      <origin
        xyz="0 0 0"
        rpy="0 0 0" />
      <geometry>
        <mesh
          filename="waist_yaw_link.STL" />
      </geometry>
      <material
        name="">
        <color
          rgba="0.752941176470588 0.752941176470588 0.752941176470588 1" />
      </material>
    </visual>
    <collision>
      <origin
        xyz="0 0 0"
        rpy="0 0 0" />
      <geometry>
        <mesh
          filename="waist_yaw_link.STL" />
      </geometry>
    </collision>
  </link>

  <joint
    name="waist_yaw_joint"
    type="fixed">
    <origin
      xyz="0 0 0"
      rpy="0 0 0" />
    <parent
      link="pelvis" />
    <child
      link="waist_yaw_link" />
    <axis
      xyz="0 0 1" />
    <limit effort="120" lower="-2.96" upper="3.14" velocity="7.0"/>
  </joint>

  <link
    name="head_yaw_link">
    <inertial>
      <origin
        xyz="-0.000198116284628826 0.000454283135208022 0.00724627742538442"
        rpy="0 0 0" />
      <mass
        value="0.0883927289639252" />
      <inertia
        ixx="0.000095"
        ixy="0.000001"
        ixz="0.000003"
        iyy="0.000076"
        iyz="0.000003"
        izz="0.000106" />
    </inertial>
    <visual>
      <origin
        xyz="0 0 0"
        rpy="0 0 0" />
      <geometry>
        <mesh
          filename="head_yaw_link.STL" />
      </geometry>
      <material
        name="">
        <color
          rgba="0.752941176470588 0.752941176470588 0.752941176470588 1" />
      </material>
    </visual>
    <collision>
      <origin
        xyz="0 0 0"
        rpy="0 0 0" />
      <geometry>
        <mesh
          filename="head_yaw_link.STL" />
      </geometry>
    </collision>
  </link>

  <joint
    name="head_yaw_joint"
    type="fixed">
    <origin
      xyz="-0.002 0 0.56508"
      rpy="0 0 0" />
    <parent
      link="waist_yaw_link" />
    <child
      link="head_yaw_link" />
    <axis
      xyz="0 0 1" />
    <limit effort="9" lower="-1.57" upper="1.57" velocity="7.2"/>
  </joint>

  <link
    name="head_pitch_link">
    <inertial>
      <origin
        xyz="-0.000274 0.004118 0.000023"
        rpy="0 0 0" />
      <mass
        value="0.230460" />
      <inertia
        ixx="0.000092"
        ixy="-0.000001"
        ixz="0.000001"
        iyy="0.000054"
        iyz="-7.30725289619866E-08"
        izz="0.000095" />
    </inertial>
    <visual>
      <origin
        xyz="0 0 0"
        rpy="0 0 0" />
      <geometry>
        <mesh
          filename="head_pitch_link.STL" />
      </geometry>
      <material
        name="">
        <color
          rgba="0.752941176470588 0.752941176470588 0.752941176470588 1" />
      </material>
    </visual>
    <collision>
      <origin
        xyz="0 0 0"
        rpy="0 0 0" />
      <geometry>
        <mesh
          filename="head_pitch_link.STL" />
      </geometry>
    </collision>
  </link>

  <joint
    name="head_pitch_joint"
    type="fixed">
    <origin
      xyz="0.01455 0 0.0304"
      rpy="0 0.2618 0" />
    <parent
      link="head_yaw_link" />
    <child
      link="head_pitch_link" />
    <axis
      xyz="0 1 0" />
    <limit effort="9" lower="-0.43" upper="0.43" velocity="7.2"/>
  </joint>

  <link
    name="head_roll_link">
    <inertial>
      <origin
        xyz="0.022467 0.001208  0.053952"
        rpy="0 0 0" />
      <mass
        value="0.844627" />
      <inertia
        ixx="0.002350"
        ixy="-0.000038"
        ixz="-0.000436"
        iyy="0.003365"
        iyz="-0.000006"
        izz="0.002875" />
    </inertial>
    <visual>
      <origin
        xyz="0 0 0"
        rpy="0 0 0" />
      <geometry>
        <mesh
          filename="head_roll_link.STL" />
      </geometry>
      <material
        name="">
        <color
          rgba="0.752941176470588 0.752941176470588 0.752941176470588 1" />
      </material>
    </visual>
    <collision>
      <origin
        xyz="0 0 0"
        rpy="0 0 0" />
      <geometry>
        <mesh
          filename="head_roll_link.STL" />
      </geometry>
    </collision>
  </link>

  <joint
    name="head_roll_joint"
    type="fixed">
    <origin
      xyz="0 0 0"
      rpy="0 0 0" />
    <parent
      link="head_pitch_link" />
    <child
      link="head_roll_link" />
    <axis
      xyz="1 0 0" />
    <limit effort="9" lower="-0.43" upper="0.43" velocity="7.2"/>
  </joint>

  <link
    name="shoulder_pitch_l_link">
    <inertial>
      <origin
        xyz="0.007540 0.064361 -0.000037"
        rpy="0 0 0" />
      <mass
        value="1.030628" />
      <inertia
        ixx="0.000536"
        ixy="0.000025"
        ixz="1.26194941072712E-08"
        iyy="0.000480"
        iyz="2.95758293199811E-08"
        izz="0.000636" />
    </inertial>
    <visual>
      <origin
        xyz="0 0 0"
        rpy="0 0 0" />
      <geometry>
        <mesh
          filename="shoulder_pitch_l_link.STL" />
      </geometry>
      <material
        name="">
        <color
          rgba="0.752941176470588 0.752941176470588 0.752941176470588 1" />
      </material>
    </visual>
    <collision>
      <origin
        xyz="0 0 0"
        rpy="0 0 0" />
      <geometry>
        <mesh
          filename="shoulder_pitch_l_link.STL" />
      </geometry>
    </collision>
  </link>

  <joint
    name="shoulder_pitch_l_joint"
    type="fixed">
    <origin
      xyz="0 0.14539 0.37721"
      rpy="0.087266 0 0" />
    <parent
      link="waist_yaw_link" />
    <child
      link="shoulder_pitch_l_link" />
    <axis
      xyz="0 1 0" />
    <limit effort="91" lower="-2.96" upper="2.96" velocity="8.8"/>
  </joint>

  <link
    name="shoulder_roll_l_link">
    <inertial>
      <origin
        xyz="0.00106653447924365 0.00220628914286614 -0.0441160803631309"
        rpy="0 0 0" />
      <mass
        value="0.412600522097283" />
      <inertia
        ixx="0.000939"
        ixy="0.000001"
        ixz="0.000001"
        iyy="0.001264"
        iyz="0.000005"
        izz="0.000896" />
    </inertial>
    <visual>
      <origin
        xyz="0 0 0"
        rpy="0 0 0" />
      <geometry>
        <mesh
          filename="shoulder_roll_l_link.STL" />
      </geometry>
      <material
        name="">
        <color
          rgba="0.752941176470588 0.752941176470588 0.752941176470588 1" />
      </material>
    </visual>
    <collision>
      <origin
        xyz="0 0 0"
        rpy="0 0 0" />
      <geometry>
        <mesh
          filename="shoulder_roll_l_link.STL" />
      </geometry>
    </collision>
  </link>

  <joint
    name="shoulder_roll_l_joint"
    type="fixed">
    <origin
      xyz="0 0.068 0"
      rpy="0 0 0" />
    <parent
      link="shoulder_pitch_l_link" />
    <child
      link="shoulder_roll_l_link" />
    <axis
      xyz="1 0 0" />
    <limit effort="60" lower="-0.2618" upper="3.4" velocity="12"/>
  </joint>

  <link
    name="shoulder_yaw_l_link">
    <inertial>
      <origin
        xyz="0.008387 0.003730 -0.112290"
        rpy="0 0 0" />
      <mass
        value="1.307604" />
      <inertia
        ixx="0.009261"
        ixy="0.000052"
        ixz="-0.000968"
        iyy="0.009283"
        iyz="-0.000413"
        izz="0.000836" />
    </inertial>
    <visual>
      <origin
        xyz="0 0 0"
        rpy="0 0 0" />
      <geometry>
        <mesh
          filename="shoulder_yaw_l_link.STL" />
      </geometry>
      <material
        name="">
        <color
          rgba="0.752941176470588 0.752941176470588 0.752941176470588 1" />
      </material>
    </visual>
    <collision>
      <origin
        xyz="0 0 0"
        rpy="0 0 0" />
      <geometry>
        <mesh
          filename="shoulder_yaw_l_link.STL" />
      </geometry>
    </collision>
  </link>

  <joint
    name="shoulder_yaw_l_joint"
    type="fixed">
    <origin
      xyz="0 0 -0.1025"
      rpy="0 0 0" />
    <parent
      link="shoulder_roll_l_link" />
    <child
      link="shoulder_yaw_l_link" />
    <axis
      xyz="0 0 1" />
    <limit effort="30" lower="-2.96" upper="2.96" velocity="7.3"/>
  </joint>

  <link
    name="elbow_pitch_l_link">
    <inertial>
      <origin
        xyz="-0.014369 -0.000090 -0.024267"
        rpy="0 0 0" />
      <mass
        value="0.222661" />
      <inertia
        ixx="0.000364"
        ixy="-0.000001"
        ixz="0.000010"
        iyy="0.000208"
        iyz="-3.96645947452354E-05"
        izz="0.000387" />
    </inertial>
    <visual>
      <origin
        xyz="0 0 0"
        rpy="0 0 0" />
      <geometry>
        <mesh
          filename="elbow_pitch_l_link.STL" />
      </geometry>
      <material
        name="">
        <color
          rgba="0.752941176470588 0.752941176470588 0.752941176470588 1" />
      </material>
    </visual>
    <collision>
      <origin
        xyz="0 0 0"
        rpy="0 0 0" />
      <geometry>
        <mesh
          filename="elbow_pitch_l_link.STL" />
      </geometry>
    </collision>
  </link>

  <joint
    name="elbow_pitch_l_joint"
    type="fixed">
    <origin
      xyz="0.02 0 -0.1975"
      rpy="0 0 0" />
    <parent
      link="shoulder_yaw_l_link" />
    <child
      link="elbow_pitch_l_link" />
    <axis
      xyz="0 1 0" />
    <limit effort="30" lower="-2.61" upper="0.261" velocity="7.3"/>
  </joint>


  <link
    name="elbow_yaw_l_link">
    <inertial>
      <origin
        xyz="0.000080 0.001150 -0.069083"
        rpy="0 0 0" />
      <mass
        value="0.990079" />
      <inertia
        ixx="0.002961"
        ixy="0.000001"
        ixz="-0.000003"
        iyy="0.002878"
        iyz="-0.000062"
        izz="0.000422" />
    </inertial>
    <visual>
      <origin
        xyz="0 0 0"
        rpy="0 0 0" />
      <geometry>
        <mesh
          filename="elbow_yaw_l_link.STL" />
      </geometry>
      <material
        name="">
        <color
          rgba="0.752941176470588 0.752941176470588 0.752941176470588 1" />
      </material>
    </visual>
    <collision>
      <origin
        xyz="0 0 0"
        rpy="0 0 0" />
      <geometry>
        <mesh
          filename="elbow_yaw_l_link.STL" />
      </geometry>
    </collision>
  </link>

  <joint
    name="elbow_yaw_l_joint"
    type="fixed">
    <origin
      xyz="-0.02 0 -0.0543"
      rpy="0 0 0" />
    <parent
      link="elbow_pitch_l_link" />
    <child
      link="elbow_yaw_l_link" />
    <axis
      xyz="0 0 1" />
    <limit effort="15" lower="-2.9671" upper="2.9671" velocity="14.6"/>
  </joint>

  <link
    name="wrist_pitch_l_link">
    <inertial>
      <origin
        xyz="0.005341 0.000652 -0.018511"
        rpy="0 0 0" />
      <mass
        value="0.266415" />
      <inertia
        ixx="0.000074"
        ixy="0.000003"
        ixz="0.000002"
        iyy="0.000114"
        iyz="0.000003"
        izz="0.000113" />
    </inertial>
    <visual>
      <origin
        xyz="0 0 0"
        rpy="0 0 0" />
      <geometry>
        <mesh
          filename="wrist_pitch_l_link.STL" />
      </geometry>
      <material
        name="">
        <color
          rgba="0.752941176470588 0.752941176470588 0.752941176470588 1" />
      </material>
    </visual>
    <collision>
      <origin
        xyz="0 0 0"
        rpy="0 0 0" />
      <geometry>
        <mesh
          filename="wrist_pitch_l_link.STL" />
      </geometry>
    </collision>
  </link>

  <joint
    name="wrist_pitch_l_joint"
    type="fixed">
    <origin
      xyz="0 0.002 -0.1887"
      rpy="0 0 0" />
    <parent
      link="elbow_yaw_l_link" />
    <child
      link="wrist_pitch_l_link" />
    <axis
      xyz="0 1 0" />
    <limit effort="9" lower="-1.3" upper="1.65" velocity="7.2"/>
  </joint>

  <link
    name="wrist_roll_l_link">
    <inertial>
      <origin
        xyz="0.001596 0.000155  -0.018822"
        rpy="0 0 0" />
      <mass
        value="0.065684" />
      <inertia
        ixx="0.000033"
        ixy="-1.01838157154324E-07"
        ixz="0.000001"
        iyy="0.000073"
        iyz="-2.28155013652257E-07"
        izz="0.000064" />
    </inertial>
    <visual>
      <origin
        xyz="0 0 0"
        rpy="0 0 0" />
      <geometry>
        <mesh
          filename="wrist_roll_l_link.STL" />
      </geometry>
      <material
        name="">
        <color
          rgba="0.752941176470588 0.752941176470588 0.752941176470588 1" />
      </material>
    </visual>
    <collision>
      <origin
        xyz="0 0 0"
        rpy="0 0 0" />
      <geometry>
        <mesh
          filename="wrist_roll_l_link.STL" />
      </geometry>
    </collision>
  </link>

  <joint
    name="wrist_roll_l_joint"
    type="fixed">
    <origin
      xyz="5.0485E-05 0 -0.02"
      rpy="0 0 0" />
    <parent
      link="wrist_pitch_l_link" />
    <child
      link="wrist_roll_l_link" />
    <axis
      xyz="1 0 0" />
    <limit effort="9" lower="-1.04" upper="0.785" velocity="7.2"/>
  </joint>

  <link
    name="shoulder_pitch_r_link">
    <inertial>
      <origin
        xyz="0.007540 -0.064361 -0.000037"
        rpy="0 0 0" />
      <mass
        value="1.030628" />
      <inertia
        ixx="0.000536"
        ixy="-0.000025"
        ixz="1.26194941072712E-08"
        iyy="0.000480"
        iyz="-2.95758293199811E-08"
        izz="0.000636" />
    </inertial>
    <visual>
      <origin
        xyz="0 0 0"
        rpy="0 0 0" />
      <geometry>
        <mesh
          filename="shoulder_pitch_r_link.STL" />
      </geometry>
      <material
        name="">
        <color
          rgba="0.752941176470588 0.752941176470588 0.752941176470588 1" />
      </material>
    </visual>
    <collision>
      <origin
        xyz="0 0 0"
        rpy="0 0 0" />
      <geometry>
        <mesh
          filename="shoulder_pitch_r_link.STL" />
      </geometry>
    </collision>
  </link>
  
  <joint
    name="shoulder_pitch_r_joint"
    type="revolute">
    <origin
      xyz="0 -0.14539 0.37721"
      rpy="-0.087266 0 0" />
    <parent
      link="waist_yaw_link" />
    <child
      link="shoulder_pitch_r_link" />
    <axis
      xyz="0 1 0" />
    <limit effort="91" lower="-2.96" upper="0" velocity="8.8"/>
  </joint>

  <link
    name="shoulder_roll_r_link">
    <inertial>
      <origin
        xyz="0.00106653447924365 -0.00220628914286614 -0.0441160803631309"
        rpy="0 0 0" />
      <mass
        value="0.412600522097283" />
      <inertia
        ixx="0.000939"
        ixy="-0.000001"
        ixz="0.000001"
        iyy="0.001264"
        iyz="-0.000005"
        izz="0.000896" />
    </inertial>
    <visual>
      <origin
        xyz="0 0 0"
        rpy="0 0 0" />
      <geometry>
        <mesh
          filename="shoulder_roll_r_link.STL" />
      </geometry>
      <material
        name="">
        <color
          rgba="0.752941176470588 0.752941176470588 0.752941176470588 1" />
      </material>
    </visual>
    <collision>
      <origin
        xyz="0 0 0"
        rpy="0 0 0" />
      <geometry>
        <mesh
          filename="shoulder_roll_r_link.STL" />
      </geometry>
    </collision>
  </link>
  <joint
    name="shoulder_roll_r_joint"
    type="revolute">
    <origin
      xyz="0 -0.068 0"
      rpy="0 0 0" />
    <parent
      link="shoulder_pitch_r_link" />
    <child
      link="shoulder_roll_r_link" />
    <axis
      xyz="1 0 0" />
    <limit effort="60" lower="-2.0" upper="-0.1" velocity="12"/>
  </joint>
  <link
    name="shoulder_yaw_r_link">
    <inertial>
      <origin
        xyz="0.008387 -0.003730 -0.112290"
        rpy="0 0 0" />
      <mass
        value="1.307604" />
      <inertia
        ixx="0.009261"
        ixy="-0.000052"
        ixz="-0.000968"
        iyy="0.009283"
        iyz="0.000413"
        izz="0.000836" />
    </inertial>
    <visual>
      <origin
        xyz="0 0 0"
        rpy="0 0 0" />
      <geometry>
        <mesh
          filename="shoulder_yaw_r_link.STL" />
      </geometry>
      <material
        name="">
        <color
          rgba="0.752941176470588 0.752941176470588 0.752941176470588 1" />
      </material>
    </visual>
    <collision>
      <origin
        xyz="0 0 0"
        rpy="0 0 0" />
      <geometry>
        <mesh
          filename="shoulder_yaw_r_link.STL" />
      </geometry>
    </collision>
  </link>
  <joint
    name="shoulder_yaw_r_joint"
    type="revolute">
    <origin
      xyz="0 0 -0.1025"
      rpy="0 0 0" />
    <parent
      link="shoulder_roll_r_link" />
    <child
      link="shoulder_yaw_r_link" />
    <axis
      xyz="0 0 1" />
    <limit effort="30" lower="0" upper="2.5" velocity="7.3"/>
  </joint>
  <link
    name="elbow_pitch_r_link">
    <inertial>
      <origin
        xyz="-0.014369 0.000090 -0.024267"
        rpy="0 0 0" />
      <mass
        value="0.222661" />
      <inertia
        ixx="0.000364"
        ixy="0.000001"
        ixz="0.000010"
        iyy="0.000208"
        iyz="3.96645947452354E-05"
        izz="0.000387" />
    </inertial>
    <visual>
      <origin
        xyz="0 0 0"
        rpy="0 0 0" />
      <geometry>
        <mesh
          filename="elbow_pitch_r_link.STL" />
      </geometry>
      <material
        name="">
        <color
          rgba="0.752941176470588 0.752941176470588 0.752941176470588 1" />
      </material>
    </visual>
    <collision>
      <origin
        xyz="0 0 0"
        rpy="0 0 0" />
      <geometry>
        <mesh
          filename="elbow_pitch_r_link.STL" />
      </geometry>
    </collision>
  </link>
  <joint
    name="elbow_pitch_r_joint"
    type="revolute">
    <origin
      xyz="0.02 0 -0.1975"
      rpy="0 0 0" />
    <parent
      link="shoulder_yaw_r_link" />
    <child
      link="elbow_pitch_r_link" />
    <axis
      xyz="0 1 0" />
    <limit effort="30" lower="-2.0" upper="0.0" velocity="7.3"/>
  </joint>
  <link
    name="elbow_yaw_r_link">
    <inertial>
      <origin
        xyz="0.000080 0.001150 -0.069083"
        rpy="0 0 0" />
      <mass
        value="0.990079" />
      <inertia
        ixx="0.002961"
        ixy="0.000001"
        ixz="-0.000003"
        iyy="0.002878"
        iyz="-0.000062"
        izz="0.000422" />
    </inertial>
    <visual>
      <origin
        xyz="0 0 0"
        rpy="0 0 0" />
      <geometry>
        <mesh
          filename="elbow_yaw_r_link.STL" />
      </geometry>
      <material
        name="">
        <color
          rgba="0.752941176470588 0.752941176470588 0.752941176470588 1" />
      </material>
    </visual>
    <collision>
      <origin
        xyz="0 0 0"
        rpy="0 0 0" />
      <geometry>
        <mesh
          filename="elbow_yaw_r_link.STL" />
      </geometry>
    </collision>
  </link>
  <joint
    name="elbow_yaw_r_joint"
    type="revolute">
    <origin
      xyz="-0.02 0 -0.0543"
      rpy="0 0 0" />
    <parent
      link="elbow_pitch_r_link" />
    <child
      link="elbow_yaw_r_link" />
    <axis
      xyz="0 0 1" />
    <limit effort="15" lower="-2.9671" upper="2.9671" velocity="14.6"/>
  </joint>
  <link
    name="wrist_pitch_r_link">
    <inertial>
      <origin
        xyz="0.005341 -0.000652 -0.018511"
        rpy="0 0 0" />
      <mass
        value="0.266415" />
      <inertia
        ixx="0.000074"
        ixy="-0.000003"
        ixz="0.000002"
        iyy="0.000114"
        iyz="-0.000003"
        izz="0.000113" />
    </inertial>
    <visual>
      <origin
        xyz="0 0 0"
        rpy="0 0 0" />
      <geometry>
        <mesh
          filename="wrist_pitch_r_link.STL" />
      </geometry>
      <material
        name="">
        <color
          rgba="0.752941176470588 0.752941176470588 0.752941176470588 1" />
      </material>
    </visual>
    <collision>
      <origin
        xyz="0 0 0"
        rpy="0 0 0" />
      <geometry>
        <mesh
          filename="wrist_pitch_r_link.STL" />
      </geometry>
    </collision>
  </link>
  <joint
    name="wrist_pitch_r_joint"
    type="revolute">
    <origin
      xyz="0 -0.002 -0.1887"
      rpy="0 0 0" />
    <parent
      link="elbow_yaw_r_link" />
    <child
      link="wrist_pitch_r_link" />
    <axis
      xyz="0 1 0" />
    <limit effort="9" lower="-0.5" upper="0.6" velocity="7.2"/>
  </joint>
  <link
    name="wrist_roll_r_link">
    <inertial>
      <origin
        xyz="0.001596 -0.000155  -0.018822"
        rpy="0 0 0" />
      <mass
        value="0.065684" />
      <inertia
        ixx="0.000033"
        ixy="1.01838157154324E-07"
        ixz="0.000001"
        iyy="0.000073"
        iyz="2.28155013652257E-07"
        izz="0.000064" />
    </inertial>
    <visual>
      <origin
        xyz="0 0 0"
        rpy="0 0 0" />
      <geometry>
        <mesh
          filename="wrist_roll_r_link.STL" />
      </geometry>
      <material
        name="">
        <color
          rgba="0.752941176470588 0.752941176470588 0.752941176470588 1" />
      </material>
    </visual>
    <collision>
      <origin
        xyz="0 0 0"
        rpy="0 0 0" />
      <geometry>
        <mesh
          filename="wrist_roll_r_link.STL" />
      </geometry>
    </collision>
  </link>
  <joint
    name="wrist_roll_r_joint"
    type="revolute">
    <origin
      xyz="5.0485E-05 0 -0.02"
      rpy="0 0 0" />
    <parent
      link="wrist_pitch_r_link" />
    <child
      link="wrist_roll_r_link" />
    <axis
      xyz="1 0 0" />
    <limit effort="9" lower="-0.5" upper="0.5" velocity="7.2"/>
  </joint>

  <!-- hand part -->
  <!-- right hand -->
  <joint name="tg2_hand_fixed" type="fixed">
    <!-- <origin xyz="0.5 0.5 0.5" rpy="-1.5707963 0 0" /> -->
    <origin xyz="0.0 0.0 -0.0375" rpy="1.5707963 0 -1.5707963" />
    <parent link="wrist_roll_r_link"/>
    <child link="palm"/>
  </joint>
  
  <!-- <link name="inspirehand_mount">
    <inertial>
      <origin xyz="0 0 0" rpy="0 0 0" />
      <mass value="0.05" />
      <inertia ixx="1e-4" ixy="0" ixz="0" iyy="1e-4" iyz="0" izz="1e-4" />
    </inertial>
    <visual>
      <origin xyz="0 0 0" rpy="0 0 0" />
      <geometry>
        <box size="0.001 0.001 0.001" />
      </geometry>
    </visual>
    <collision>
      <origin xyz="0 0 0" rpy="0 0 0" />
      <geometry>
        <box size="0.001 0.001 0.001" />
      </geometry>
    </collision>
  </link>

  <joint name="inspirehand_mount_joint" type="fixed">
    <origin xyz="0 -0.07 0" rpy="0 -1.5708 0" />
    <parent link="inspirehand_mount" />
    <child link="palm" />
  </joint> -->

  <link
    name="palm">
    <inertial>
      <origin
        xyz="-0.0025264 -0.066047 0.0019598"
        rpy="0 0 0" />
      <mass
        value="0.3" />
      <inertia
        ixx="0.00012281"
        ixy="2.1711E-06"
        ixz="1.7709E-06"
        iyy="8.3831E-05"
        iyz="-1.655E-06"
        izz="7.6663E-05" />
    </inertial>
    <visual>
      <origin
        xyz="0 0 0"
        rpy="0 0 0" />
      <geometry>
        <mesh
          filename="palm.STL" />
      </geometry>
      <material
        name="">
        <color
          rgba="1 1 1 1" />
      </material>
    </visual>
    <collision>
      <origin
        xyz="0 0 0"
        rpy="0 0 0" />
      <geometry>
        <mesh
          filename="palm.STL" />
      </geometry>
    </collision>
  </link>

  <!-- Helper link to visualize palm +Z direction -->
  <!-- Offset along palm +Z by 5 cm; adjust if needed -->
  <!-- <joint name="palm_dir_joint" type="fixed">
    
    <origin xyz="-0.2 0.0 0.0" rpy="0 0 0" />
    <parent link="palm" />
    <child link="palm_dir" />
  </joint> -->

  <!-- offset along finger direction
  <joint name="palm_dir_joint" type="fixed">
    
    <origin xyz="0.0 -1.0 0.0" rpy="0 0 0" />
    <parent link="palm" />
    <child link="palm_dir" />
  </joint> -->

  <!-- <link name="palm_dir">
    <inertial>
      <origin xyz="0 0 0" rpy="0 0 0" />
      <mass value="0.0001" />
      <inertia ixx="1e-8" ixy="0" ixz="0" iyy="1e-8" iyz="0" izz="1e-8" />
    </inertial>
    <visual>
      <origin xyz="0 0 0" rpy="0 0 0" />
      <geometry>
        <box size="0.02 0.02 0.02" />
      </geometry>
      <material name="PalmDirMat">
        <color rgba="0 0 1 1" />
      </material>
    </visual>
    <collision>
      <origin xyz="0 0 0" rpy="0 0 0" />
      <geometry>
        <box size="0.02 0.02 0.02" />
      </geometry>
    </collision>
  </link> -->

  <!-- index finger -->
  <joint
    name="index_joint_0"
    type="revolute">
    <origin
      xyz="0.00028533 -0.1366 -0.027269"
      rpy="-0.034907 0 3.1416" />
  <parent link="palm" />
  <child link="index_link_0" />
    <axis xyz="0 0 -1" />
    <limit
      lower="0"
      upper="1.1"
      effort="50"
      velocity="1" />
  </joint>

  <link
    name="index_link_0">
    <inertial>
      <origin
        xyz="0.0031774 0.017383 0.00090008"
        rpy="0 0 0" />
      <mass
        value="0.05" />
      <inertia
        ixx="6.6232E-07"
        ixy="1.5775E-08"
        ixz="1.8782E-12"
        iyy="2.1146E-07"
        iyz="5.067E-12"
        izz="6.9398E-07" />
    </inertial>
    <visual>
      <origin
        xyz="0 0 0"
        rpy="0 0 0" />
      <geometry>
        <mesh
          filename="index_link_0.STL" />
      </geometry>
      <material
        name="">
        <color
          rgba="1 1 1 1" />
      </material>
    </visual>
    <collision>
      <origin
        xyz="0 0 0"
        rpy="0 0 0" />
      <geometry>
        <mesh
          filename="index_link_0.STL" />
      </geometry>
    </collision>
  </link>

  <joint
    name="index_joint_1"
    type="revolute">
    <origin
      xyz="0.0070171 0.037468 -0.00215"
      rpy="0 0 0" />
  <parent
      link="index_link_0" />
  <child
      link="index_link_1" />
    <axis
      xyz="0 0 -1" />
    <limit
      lower="0"
      upper="1.7"
      effort="50"
      velocity="1" />
    <mimic joint="index_joint_0" multiplier="1.54545" offset="0" />
  </joint>

  <link
    name="index_link_1">
    <inertial>
      <origin
        xyz="-0.0019697 0.019589 0.00305"
        rpy="0 0 0" />
      <mass
        value="0.025" />
      <inertia
        ixx="7.6111E-07"
        ixy="-8.7637E-08"
        ixz="-4.2766E-13"
        iyy="9.6076E-08"
        iyz="-1.2085E-12"
        izz="7.8179E-07" />
    </inertial>
    <visual>
      <origin
        xyz="0 0 0"
        rpy="0 0 0" />
      <geometry>
        <mesh
          filename="index_link_1.STL" />
      </geometry>
      <material
        name="">
        <color
          rgba="1 1 1 1" />
      </material>
    </visual>
    <collision>
      <origin
        xyz="0 0 0"
        rpy="0 0 0" />
      <geometry>
        <mesh
          filename="index_link_1.STL" />
      </geometry>
    </collision>
  </link>

  <joint name="index_tip_fixed" type="fixed">
    <origin xyz="0.005 0.035 0.002" rpy="0 0 0" />
    <parent link="index_link_1" />
    <child link="index_tip" />
  </joint>

  <link name="index_tip">
    <inertial>
      <origin xyz="0 0 0" rpy="0 0 0" />
      <mass value="1e-6" />
      <inertia ixx="1e-9" ixy="0" ixz="0" iyy="1e-9" iyz="0" izz="1e-9" />
    </inertial>
  </link>

<!-- middle finger -->

  <joint
    name="middle_joint_0"
    type="revolute">
    <origin
      xyz="0.00028533 -0.1371 -0.00795"
      rpy="0 0 3.1416" />
    <parent link="palm" />
    <child link="middle_link_0" />
    <axis xyz="0 0 -1" />
    <limit
      lower="0"
      upper="1.1"
      effort="50"
      velocity="1" />
  </joint>

  <link
    name="middle_link_0">
    <inertial>
      <origin
        xyz="0.0030737 0.017402 0.00090013"
        rpy="0 0 0" />
      <mass
        value="0.05" />
      <inertia
        ixx="6.6211E-07"
        ixy="1.8461E-08"
        ixz="1.798E-12"
        iyy="2.1167E-07"
        iyz="6.6568E-12"
        izz="6.9397E-07" />
    </inertial>
    <visual>
      <origin
        xyz="0 0 0"
        rpy="0 0 0" />
      <geometry>
        <mesh
          filename="middle_link_0.STL" />
      </geometry>
      <material
        name="">
        <color
          rgba="1 1 1 1" />
      </material>
    </visual>
    <collision>
      <origin
        xyz="0 0 0"
        rpy="0 0 0" />
      <geometry>
        <mesh
          filename="middle_link_0.STL" />
      </geometry>
    </collision>
  </link>

  <joint
    name="middle_joint_1"
    type="revolute">
    <origin
      xyz="0.0067937 0.037509 -0.00215"
      rpy="0 0 0" />
    <parent
      link="middle_link_0" />
    <child
      link="middle_link_1" />
    <axis
      xyz="0 0 -1" />
    <limit
      lower="0"
      upper="1.7"
      effort="50"
      velocity="1" />
    <mimic joint="middle_joint_0" multiplier="1.54545" offset="0" />
  </joint>

  <link
    name="middle_link_1">
    <inertial>
      <origin
        xyz="-0.001921 0.020796 0.00305"
        rpy="0 0 0" />
      <mass
        value="0.025" />
      <inertia
        ixx="9.5822E-07"
        ixy="-1.1425E-07"
        ixz="-2.4866E-12"
        iyy="1.0646E-07"
        iyz="-5.9101E-12"
        izz="9.8384E-07" />
    </inertial>
    <visual>
      <origin
        xyz="0 0 0"
        rpy="0 0 0" />
      <geometry>
        <mesh
          filename="middle_link_1.STL" />
      </geometry>
      <material
        name="">
        <color
          rgba="1 1 1 1" />
      </material>
    </visual>
    <collision>
      <origin
        xyz="0 0 0"
        rpy="0 0 0" />
      <geometry>
        <mesh
          filename="middle_link_1.STL" />
      </geometry>
    </collision>
  </link>

  <joint name="middle_tip_fixed" type="fixed">
    <origin xyz="0.005 0.035 0.002" rpy="0 0 0" />
    <parent link="middle_link_1" />
    <child link="middle_tip" />
  </joint>

  <link name="middle_tip">
    <inertial>
      <origin xyz="0 0 0" rpy="0 0 0" />
      <mass value="1e-6" />
      <inertia ixx="1e-9" ixy="0" ixz="0" iyy="1e-9" iyz="0" izz="1e-9" />
    </inertial>
  </link>
  
 <!-- ring finger -->
  <joint
    name="ring_joint_0"
    type="revolute">
    <origin
      xyz="0.00028533 -0.13681 0.0112844"
      rpy="0.05236 0 -3.1416" />
    <parent link="palm" />
    <child link="ring_link_0" />
    <axis xyz="0 0 -1" />
    <limit
      lower="0"
      upper="1.1"
      effort="50"
      velocity="1" />
  </joint>

  <link
    name="ring_link_0">
    <inertial>
      <origin
        xyz="0.0030737 0.017402 0.00090015"
        rpy="0 0 0" />
      <mass
        value="0.05" />
      <inertia
        ixx="6.6211E-07"
        ixy="1.8461E-08"
        ixz="1.5739E-12"
        iyy="2.1167E-07"
        iyz="6.6326E-12"
        izz="6.9397E-07" />
    </inertial>
    <visual>
      <origin
        xyz="0 0 0"
        rpy="0 0 0" />
      <geometry>
        <mesh
          filename="ring_link_0.STL" />
      </geometry>
      <material
        name="">
        <color
          rgba="1 1 1 1" />
      </material>
    </visual>
    <collision>
      <origin
        xyz="0 0 0"
        rpy="0 0 0" />
      <geometry>
        <mesh
          filename="ring_link_0.STL" />
      </geometry>
    </collision>
  </link>

  <joint
    name="ring_joint_1"
    type="revolute">
    <origin
      xyz="0.0067937 0.037509 -0.00215"
      rpy="0 0 0" />
    <parent
      link="ring_link_0" />
    <child
      link="ring_link_1" />
    <axis
      xyz="0 0 -1" />
    <limit
      lower="0"
      upper="1.7"
      effort="50"
      velocity="1" />
    <mimic joint="ring_joint_0" multiplier="1.54545" offset="0" />
  </joint>

  <link
    name="ring_link_1">
    <inertial>
      <origin
        xyz="-0.0021753 0.019567 0.00305"
        rpy="0 0 0" />
      <mass
        value="0.025" />
      <inertia
        ixx="7.6286E-07"
        ixy="-8.0635E-08"
        ixz="-6.1735E-13"
        iyy="9.431E-08"
        iyz="-5.5495E-13"
        izz="7.8177E-07" />
    </inertial>
    <visual>
      <origin
        xyz="0 0 0"
        rpy="0 0 0" />
      <geometry>
        <mesh
          filename="ring_link_1.STL" />
      </geometry>
      <material
        name="">
        <color
          rgba="1 1 1 1" />
      </material>
    </visual>
    <collision>
      <origin
        xyz="0 0 0"
        rpy="0 0 0" />
      <geometry>
        <mesh
          filename="ring_link_1.STL" />
      </geometry>
    </collision>
  </link>

  <joint name="ring_tip_fixed" type="fixed">
    <origin xyz="0.005 0.035 0.002" rpy="0 0 0" />
    <parent link="ring_link_1" />
    <child link="ring_tip" />
  </joint>

  <link name="ring_tip">
    <inertial>
      <origin xyz="0 0 0" rpy="0 0 0" />
      <mass value="1e-6" />
      <inertia ixx="1e-9" ixy="0" ixz="0" iyy="1e-9" iyz="0" izz="1e-9" />
    </inertial>
  </link>

<!-- little finger -->
  <joint name="little_joint_0" type="revolute">
  <!-- The joint origin defines the transform from parent link to joint frame -->
  <origin xyz="0.00028533 -0.13551 0.030477" rpy="0.10472 0 -3.1416"/>

  <!-- Parent and child links -->
  <parent link="palm"/>
  <child link="little_link_0"/>

    <!-- Axis of rotation (in joint frame) -->
    <axis xyz="0 0 -1"/>

    <!-- Joint limits -->
    <limit lower="0" upper="1.1" effort="100.0" velocity="1.0"/>
  </joint>

  <link
    name="little_link_0">
    <inertial>
      <origin
        xyz="0.0030737 0.017402 0.00090014"
        rpy="0 0 0" />
      <mass
        value="0.05" />
      <inertia
        ixx="6.6211E-07"
        ixy="1.8461E-08"
        ixz="1.6126E-12"
        iyy="2.1167E-07"
        iyz="6.6785E-12"
        izz="6.9398E-07" />
    </inertial>
    <visual>
      <origin
        xyz="0 0 0"
        rpy="0 0 0" />
      <geometry>
        <mesh
          filename="little_link_0.STL" />
      </geometry>
      <material
        name="">
        <color
          rgba="1 1 1 1" />
      </material>
    </visual>
    <collision>
      <origin
        xyz="0 0 0"
        rpy="0 0 0" />
      <geometry>
        <mesh
          filename="little_link_0.STL" />
      </geometry>
    </collision>
  </link>

  <joint
    name="little_joint_1"
    type="revolute">
    <origin
      xyz="0.0067937 0.037509 -0.00215"
      rpy="0 0 0" />
    <parent
      link="little_link_0" />
    <child
      link="little_link_1" />
    <axis
      xyz="0 0 -1" />
    <limit
      lower="0"
      upper="1.7"
      effort="50"
      velocity="1" />
    <mimic joint="little_joint_0" multiplier="1.54545" offset="0" />
  </joint>

  <link
    name="little_link_1">
    <inertial>
      <origin
        xyz="-0.0024748 0.016203 0.0030531"
        rpy="0 0 0" />
      <mass
        value="0.025" />
      <inertia
        ixx="4.3913E-07"
        ixy="-4.1418E-08"
        ixz="3.7169E-11"
        iyy="7.0247E-08"
        iyz="-5.8612E-11"
        izz="4.4867E-07" />
    </inertial>
    <visual>
      <origin
        xyz="0 0 0"
        rpy="0 0 0" />
      <geometry>
        <mesh
          filename="little_link_1.STL" />
      </geometry>
      <material
        name="">
        <color
          rgba="1 1 1 1" />
      </material>
    </visual>
    <collision>
      <origin
        xyz="0 0 0"
        rpy="0 0 0" />
      <geometry>
        <mesh
          filename="little_link_1.STL" />
      </geometry>
    </collision>
  </link>

  <joint name="little_tip_fixed" type="fixed">
    <origin xyz="0.005 0.035 0.003" rpy="0 0 0" />
    <parent link="little_link_1" />
    <child link="little_tip" />
  </joint>

  <link name="little_tip">
    <inertial>
      <origin xyz="0 0 0" rpy="0 0 0" />
      <mass value="1e-6" />
      <inertia ixx="1e-9" ixy="0" ixz="0" iyy="1e-9" iyz="0" izz="1e-9" />
    </inertial>
  </link>
 
  <!-- thumb -->
  
  
<joint name="thumb_joint_0" type="revolute">
  <!-- Transform from parent (base_link) to this joint frame -->
  <origin xyz="-0.02296 -0.05885 -0.02045" rpy="1.5708 -1.5708 0"/>

  <!-- Parent and child links -->
  <parent link="palm"/>
  <child link="thumb_link_0"/>

  <!-- Axis of rotation -->
  <axis xyz="0 0 -1"/>

  <!-- Joint limits -->
  <limit lower="0.3" upper="1.2" effort="50.0" velocity="1.0"/>
</joint>

  <link
    name="thumb_link_0">
    <inertial>
      <origin
        xyz="-0.0078715 0.0065154 0.00388"
        rpy="0 0 0" />
      <mass
        value="0.05" />
      <inertia
        ixx="5.816E-08"
        ixy="1.4539E-08"
        ixz="4.491E-09"
        iyy="7.9161E-08"
        iyz="-1.8727E-09"
        izz="6.7433E-08" />
    </inertial>
    <visual>
      <origin
        xyz="0 0 0"
        rpy="0 0 0" />
      <geometry>
        <mesh
          filename="thumb_link_0.STL" />
      </geometry>
      <material
        name="">
        <color
          rgba="1 1 1 1" />
      </material>
    </visual>
    <collision>
      <origin
        xyz="0 0 0"
        rpy="0 0 0" />
      <geometry>
        <mesh
          filename="thumb_link_0.STL" />
      </geometry>
    </collision>
  </link>

  <joint
    name="thumb_joint_1"
    type="revolute">
    <origin
      xyz="-0.012782 0.013348 0.0022"
      rpy="1.5708 0 2.8587" />
    <parent
      link="thumb_link_0" />
    <child
      link="thumb_link_1" />
    <axis
      xyz="0 0 1" />
    <limit
      lower="0"
      upper="0.5"
      effort="50"
      velocity="1" />
  </joint>

  <link
    name="thumb_link_1">
    <inertial>
      <origin
        xyz="0.021932 0.012785 -0.0047886"
        rpy="0 0 0" />
      <mass
        value="0.03" />
      <inertia
        ixx="1.5687E-06"
        ixy="-7.8296E-07"
        ixz="8.9144E-10"
        iyy="1.7353E-06"
        iyz="-1.0191E-09"
        izz="2.786E-06" />
    </inertial>
    <visual>
      <origin
        xyz="0 0 0"
        rpy="0 0 0" />
      <geometry>
        <mesh
          filename="thumb_link_1.STL" />
      </geometry>
      <material
        name="">
        <color
          rgba="1 1 1 1" />
      </material>
    </visual>
    <collision>
      <origin
        xyz="0 0 0"
        rpy="0 0 0" />
      <geometry>
        <mesh
          filename="thumb_link_1.STL" />
      </geometry>
    </collision>
  </link>

<joint name="thumb_joint_2" type="revolute">
  <!-- Transform from parent (Link44) to this joint frame -->
  <origin xyz="0.05507 0.025553 -0.00355" rpy="-3.1416 0 -3.1416"/>

  <!-- Parent and child links -->
  <parent link="thumb_link_1"/>
  <child link="thumb_link_2"/>

  <!-- Axis of rotation (in joint frame) -->
  <axis xyz="0 0 -1"/>

  <!-- Joint limits -->
  <limit lower="0" upper="0.5" effort="50.0" velocity="1.0"/>
  <mimic joint="thumb_joint_1" multiplier="1.0" offset="0" />
</joint>

  <link
    name="thumb_link_2">
    <inertial>
      <origin
        xyz="-0.0060688 0.011295 0.00099972"
        rpy="0 0 0" />
      <mass
        value="0.025" />
      <inertia
        ixx="3.6981E-07"
        ixy="9.8581E-08"
        ixz="-4.7472E-12"
        iyy="3.2394E-07"
        iyz="-1.0931E-12"
        izz="4.6531E-07" />
    </inertial>
    <visual>
      <origin
        xyz="0 0 0"
        rpy="0 0 0" />
      <geometry>
        <mesh
          filename="thumb_link_2.STL" />
      </geometry>
      <material
        name="">
        <color
          rgba="1 1 1 1" />
      </material>
    </visual>
    <collision>
      <origin
        xyz="0 0 0"
        rpy="0 0 0" />
      <geometry>
        <mesh
          filename="thumb_link_2.STL" />
      </geometry>
    </collision>
  </link>

  <joint
    name="thumb_joint_3"
    type="revolute">
    <origin
      xyz="-0.016763 0.023079 -0.00255"
      rpy="0 0 0" />
    <parent
      link="thumb_link_2" />
    <child
      link="thumb_link_3" />
    <axis
      xyz="0 0 -1" />
    <limit
      lower="0"
      upper="0.4"
      effort="50"
      velocity="1" />
    <mimic joint="thumb_joint_2" multiplier="0.8" offset="0" />
  </joint>

  <link
    name="thumb_link_3">
    <inertial>
      <origin
        xyz="-0.0092888 0.0049529 0.0035533"
        rpy="0 0 0" />
      <mass
        value="0.02" />
      <inertia
        ixx="1.3632E-07"
        ixy="5.6788E-08"
        ixz="-9.2801E-11"
        iyy="1.4052E-07"
        iyz="1.2283E-10"
        izz="2.0026E-07" />
    </inertial>
    <visual>
      <origin
        xyz="0 0 0"
        rpy="0 0 0" />
      <geometry>
        <mesh
          filename="thumb_link_3.STL" />
      </geometry>
      <material
        name="">
        <color
          rgba="1 1 1 1" />
      </material>
    </visual>
    <collision>
      <origin
        xyz="0 0 0"
        rpy="0 0 0" />
      <geometry>
        <mesh
          filename="thumb_link_3.STL" />
      </geometry>
    </collision>
  </link>

  <joint name="thumb_tip_fixed" type="fixed">
    <origin xyz="-0.01 0.015 0.005" rpy="0 0 0" />
    <parent link="thumb_link_3" />
    <child link="thumb_tip" />
  </joint>

  <link name="thumb_tip">
    <inertial>
      <origin xyz="0 0 0" rpy="0 0 0" />
      <mass value="1e-6" />
      <inertia ixx="1e-9" ixy="0" ixz="0" iyy="1e-9" iyz="0" izz="1e-9" />
    </inertial>
  </link>
</robot>
